2020-04-10 03:38:31,313 - telegram.vendor.ptb_urllib3.urllib3.connectionpool - WARNING - Retrying (Retry(total=2, connect=None, read=None, redirect=None)) after connection broken by 'NewConnectionError('<telegram.vendor.ptb_urllib3.urllib3.connection.VerifiedHTTPSConnection object at 0x111e5c128>: Failed to establish a new connection: [Errno 61] Connection refused')': /bot1241247575:AAF_4zWZ9PAwDzXEMXBR1UpZqIu-apaNee4/getMe
2020-04-10 03:38:31,339 - telegram.vendor.ptb_urllib3.urllib3.connectionpool - WARNING - Retrying (Retry(total=1, connect=None, read=None, redirect=None)) after connection broken by 'NewConnectionError('<telegram.vendor.ptb_urllib3.urllib3.connection.VerifiedHTTPSConnection object at 0x11180c630>: Failed to establish a new connection: [Errno 61] Connection refused')': /bot1241247575:AAF_4zWZ9PAwDzXEMXBR1UpZqIu-apaNee4/getMe
2020-04-10 03:38:31,366 - telegram.vendor.ptb_urllib3.urllib3.connectionpool - WARNING - Retrying (Retry(total=0, connect=None, read=None, redirect=None)) after connection broken by 'NewConnectionError('<telegram.vendor.ptb_urllib3.urllib3.connection.VerifiedHTTPSConnection object at 0x111e5c240>: Failed to establish a new connection: [Errno 61] Connection refused')': /bot1241247575:AAF_4zWZ9PAwDzXEMXBR1UpZqIu-apaNee4/getMe
2020-04-10 03:38:52,929 - telegram.ext.updater - INFO - Received signal 2 (SIGINT), stopping...
2020-04-10 03:40:38,563 - telegram.ext.updater - INFO - Received signal 2 (SIGINT), stopping...
2020-04-10 03:42:14,148 - telegram.vendor.ptb_urllib3.urllib3.connectionpool - WARNING - Retrying (Retry(total=2, connect=None, read=None, redirect=None)) after connection broken by 'NewConnectionError('<telegram.vendor.ptb_urllib3.urllib3.connection.VerifiedHTTPSConnection object at 0x111fe8908>: Failed to establish a new connection: [Errno 61] Connection refused')': /bot1241247575:AAF_4zWZ9PAwDzXEMXBR1UpZqIu-apaNee4/getUpdates
2020-04-10 03:42:14,178 - telegram.vendor.ptb_urllib3.urllib3.connectionpool - WARNING - Retrying (Retry(total=1, connect=None, read=None, redirect=None)) after connection broken by 'NewConnectionError('<telegram.vendor.ptb_urllib3.urllib3.connection.VerifiedHTTPSConnection object at 0x111fe89b0>: Failed to establish a new connection: [Errno 61] Connection refused')': /bot1241247575:AAF_4zWZ9PAwDzXEMXBR1UpZqIu-apaNee4/getUpdates
2020-04-10 03:42:14,211 - telegram.vendor.ptb_urllib3.urllib3.connectionpool - WARNING - Retrying (Retry(total=0, connect=None, read=None, redirect=None)) after connection broken by 'NewConnectionError('<telegram.vendor.ptb_urllib3.urllib3.connection.VerifiedHTTPSConnection object at 0x111fe8978>: Failed to establish a new connection: [Errno 61] Connection refused')': /bot1241247575:AAF_4zWZ9PAwDzXEMXBR1UpZqIu-apaNee4/getUpdates
2020-04-10 03:42:14,238 - telegram.ext.updater - ERROR - Error while getting Updates: urllib3 HTTPError HTTPSConnectionPool(host='api.telegram.org', port=443): Max retries exceeded with url: /bot1241247575:AAF_4zWZ9PAwDzXEMXBR1UpZqIu-apaNee4/getUpdates (Caused by NewConnectionError('<telegram.vendor.ptb_urllib3.urllib3.connection.VerifiedHTTPSConnection object at 0x111fe8748>: Failed to establish a new connection: [Errno 61] Connection refused'))
2020-04-10 03:42:14,238 - telegram.ext.dispatcher - ERROR - An uncaught error was raised while handling the error
Traceback (most recent call last):
  File "/Users/ba/Documents/venv/lib/python3.7/site-packages/telegram/ext/dispatcher.py", line 376, in process_update
    self.dispatch_error(None, update)
  File "/Users/ba/Documents/venv/lib/python3.7/site-packages/telegram/ext/dispatcher.py", line 530, in dispatch_error
    callback(self.bot, update, error)
TypeError: error() takes 2 positional arguments but 3 were given
2020-04-10 03:42:15,276 - telegram.vendor.ptb_urllib3.urllib3.connectionpool - WARNING - Retrying (Retry(total=2, connect=None, read=None, redirect=None)) after connection broken by 'NewConnectionError('<telegram.vendor.ptb_urllib3.urllib3.connection.VerifiedHTTPSConnection object at 0x111fe8320>: Failed to establish a new connection: [Errno 61] Connection refused')': /bot1241247575:AAF_4zWZ9PAwDzXEMXBR1UpZqIu-apaNee4/getUpdates
2020-04-10 03:42:15,303 - telegram.vendor.ptb_urllib3.urllib3.connectionpool - WARNING - Retrying (Retry(total=1, connect=None, read=None, redirect=None)) after connection broken by 'NewConnectionError('<telegram.vendor.ptb_urllib3.urllib3.connection.VerifiedHTTPSConnection object at 0x112006080>: Failed to establish a new connection: [Errno 61] Connection refused')': /bot1241247575:AAF_4zWZ9PAwDzXEMXBR1UpZqIu-apaNee4/getUpdates
2020-04-10 03:42:15,328 - telegram.vendor.ptb_urllib3.urllib3.connectionpool - WARNING - Retrying (Retry(total=0, connect=None, read=None, redirect=None)) after connection broken by 'NewConnectionError('<telegram.vendor.ptb_urllib3.urllib3.connection.VerifiedHTTPSConnection object at 0x112006128>: Failed to establish a new connection: [Errno 61] Connection refused')': /bot1241247575:AAF_4zWZ9PAwDzXEMXBR1UpZqIu-apaNee4/getUpdates
2020-04-10 03:42:15,353 - telegram.ext.updater - ERROR - Error while getting Updates: urllib3 HTTPError HTTPSConnectionPool(host='api.telegram.org', port=443): Max retries exceeded with url: /bot1241247575:AAF_4zWZ9PAwDzXEMXBR1UpZqIu-apaNee4/getUpdates (Caused by NewConnectionError('<telegram.vendor.ptb_urllib3.urllib3.connection.VerifiedHTTPSConnection object at 0x112006208>: Failed to establish a new connection: [Errno 61] Connection refused'))
2020-04-10 03:42:15,353 - telegram.ext.dispatcher - ERROR - An uncaught error was raised while handling the error
Traceback (most recent call last):
  File "/Users/ba/Documents/venv/lib/python3.7/site-packages/telegram/ext/dispatcher.py", line 376, in process_update
    self.dispatch_error(None, update)
  File "/Users/ba/Documents/venv/lib/python3.7/site-packages/telegram/ext/dispatcher.py", line 530, in dispatch_error
    callback(self.bot, update, error)
TypeError: error() takes 2 positional arguments but 3 were given
2020-04-10 03:42:16,895 - telegram.vendor.ptb_urllib3.urllib3.connectionpool - WARNING - Retrying (Retry(total=2, connect=None, read=None, redirect=None)) after connection broken by 'NewConnectionError('<telegram.vendor.ptb_urllib3.urllib3.connection.VerifiedHTTPSConnection object at 0x112006438>: Failed to establish a new connection: [Errno 61] Connection refused')': /bot1241247575:AAF_4zWZ9PAwDzXEMXBR1UpZqIu-apaNee4/getUpdates
2020-04-10 03:42:16,920 - telegram.vendor.ptb_urllib3.urllib3.connectionpool - WARNING - Retrying (Retry(total=1, connect=None, read=None, redirect=None)) after connection broken by 'NewConnectionError('<telegram.vendor.ptb_urllib3.urllib3.connection.VerifiedHTTPSConnection object at 0x112006518>: Failed to establish a new connection: [Errno 61] Connection refused')': /bot1241247575:AAF_4zWZ9PAwDzXEMXBR1UpZqIu-apaNee4/getUpdates
2020-04-10 03:42:16,944 - telegram.vendor.ptb_urllib3.urllib3.connectionpool - WARNING - Retrying (Retry(total=0, connect=None, read=None, redirect=None)) after connection broken by 'NewConnectionError('<telegram.vendor.ptb_urllib3.urllib3.connection.VerifiedHTTPSConnection object at 0x1120065c0>: Failed to establish a new connection: [Errno 61] Connection refused')': /bot1241247575:AAF_4zWZ9PAwDzXEMXBR1UpZqIu-apaNee4/getUpdates
2020-04-10 03:42:16,968 - telegram.ext.updater - ERROR - Error while getting Updates: urllib3 HTTPError HTTPSConnectionPool(host='api.telegram.org', port=443): Max retries exceeded with url: /bot1241247575:AAF_4zWZ9PAwDzXEMXBR1UpZqIu-apaNee4/getUpdates (Caused by NewConnectionError('<telegram.vendor.ptb_urllib3.urllib3.connection.VerifiedHTTPSConnection object at 0x1120066a0>: Failed to establish a new connection: [Errno 61] Connection refused'))
2020-04-10 03:42:16,969 - telegram.ext.dispatcher - ERROR - An uncaught error was raised while handling the error
Traceback (most recent call last):
  File "/Users/ba/Documents/venv/lib/python3.7/site-packages/telegram/ext/dispatcher.py", line 376, in process_update
    self.dispatch_error(None, update)
  File "/Users/ba/Documents/venv/lib/python3.7/site-packages/telegram/ext/dispatcher.py", line 530, in dispatch_error
    callback(self.bot, update, error)
TypeError: error() takes 2 positional arguments but 3 were given
2020-04-10 03:42:19,263 - telegram.vendor.ptb_urllib3.urllib3.connectionpool - WARNING - Retrying (Retry(total=2, connect=None, read=None, redirect=None)) after connection broken by 'NewConnectionError('<telegram.vendor.ptb_urllib3.urllib3.connection.VerifiedHTTPSConnection object at 0x1120063c8>: Failed to establish a new connection: [Errno 61] Connection refused')': /bot1241247575:AAF_4zWZ9PAwDzXEMXBR1UpZqIu-apaNee4/getUpdates
2020-04-10 03:42:19,292 - telegram.vendor.ptb_urllib3.urllib3.connectionpool - WARNING - Retrying (Retry(total=1, connect=None, read=None, redirect=None)) after connection broken by 'NewConnectionError('<telegram.vendor.ptb_urllib3.urllib3.connection.VerifiedHTTPSConnection object at 0x111fe8d30>: Failed to establish a new connection: [Errno 61] Connection refused')': /bot1241247575:AAF_4zWZ9PAwDzXEMXBR1UpZqIu-apaNee4/getUpdates
2020-04-10 03:42:19,320 - telegram.vendor.ptb_urllib3.urllib3.connectionpool - WARNING - Retrying (Retry(total=0, connect=None, read=None, redirect=None)) after connection broken by 'NewConnectionError('<telegram.vendor.ptb_urllib3.urllib3.connection.VerifiedHTTPSConnection object at 0x111fe8e80>: Failed to establish a new connection: [Errno 61] Connection refused')': /bot1241247575:AAF_4zWZ9PAwDzXEMXBR1UpZqIu-apaNee4/getUpdates
2020-04-10 03:42:19,344 - telegram.ext.updater - ERROR - Error while getting Updates: urllib3 HTTPError HTTPSConnectionPool(host='api.telegram.org', port=443): Max retries exceeded with url: /bot1241247575:AAF_4zWZ9PAwDzXEMXBR1UpZqIu-apaNee4/getUpdates (Caused by NewConnectionError('<telegram.vendor.ptb_urllib3.urllib3.connection.VerifiedHTTPSConnection object at 0x111fe8fd0>: Failed to establish a new connection: [Errno 61] Connection refused'))
2020-04-10 03:42:19,344 - telegram.ext.dispatcher - ERROR - An uncaught error was raised while handling the error
Traceback (most recent call last):
  File "/Users/ba/Documents/venv/lib/python3.7/site-packages/telegram/ext/dispatcher.py", line 376, in process_update
    self.dispatch_error(None, update)
  File "/Users/ba/Documents/venv/lib/python3.7/site-packages/telegram/ext/dispatcher.py", line 530, in dispatch_error
    callback(self.bot, update, error)
TypeError: error() takes 2 positional arguments but 3 were given
2020-04-10 03:42:22,763 - telegram.vendor.ptb_urllib3.urllib3.connectionpool - WARNING - Retrying (Retry(total=2, connect=None, read=None, redirect=None)) after connection broken by 'NewConnectionError('<telegram.vendor.ptb_urllib3.urllib3.connection.VerifiedHTTPSConnection object at 0x111fe8be0>: Failed to establish a new connection: [Errno 61] Connection refused')': /bot1241247575:AAF_4zWZ9PAwDzXEMXBR1UpZqIu-apaNee4/getUpdates
2020-04-10 03:42:22,788 - telegram.vendor.ptb_urllib3.urllib3.connectionpool - WARNING - Retrying (Retry(total=1, connect=None, read=None, redirect=None)) after connection broken by 'NewConnectionError('<telegram.vendor.ptb_urllib3.urllib3.connection.VerifiedHTTPSConnection object at 0x111fe8978>: Failed to establish a new connection: [Errno 61] Connection refused')': /bot1241247575:AAF_4zWZ9PAwDzXEMXBR1UpZqIu-apaNee4/getUpdates
2020-04-10 03:42:22,823 - telegram.vendor.ptb_urllib3.urllib3.connectionpool - WARNING - Retrying (Retry(total=0, connect=None, read=None, redirect=None)) after connection broken by 'NewConnectionError('<telegram.vendor.ptb_urllib3.urllib3.connection.VerifiedHTTPSConnection object at 0x111fe84a8>: Failed to establish a new connection: [Errno 61] Connection refused')': /bot1241247575:AAF_4zWZ9PAwDzXEMXBR1UpZqIu-apaNee4/getUpdates
2020-04-10 03:42:22,848 - telegram.ext.updater - ERROR - Error while getting Updates: urllib3 HTTPError HTTPSConnectionPool(host='api.telegram.org', port=443): Max retries exceeded with url: /bot1241247575:AAF_4zWZ9PAwDzXEMXBR1UpZqIu-apaNee4/getUpdates (Caused by NewConnectionError('<telegram.vendor.ptb_urllib3.urllib3.connection.VerifiedHTTPSConnection object at 0x111f790b8>: Failed to establish a new connection: [Errno 61] Connection refused'))
2020-04-10 03:42:22,849 - telegram.ext.dispatcher - ERROR - An uncaught error was raised while handling the error
Traceback (most recent call last):
  File "/Users/ba/Documents/venv/lib/python3.7/site-packages/telegram/ext/dispatcher.py", line 376, in process_update
    self.dispatch_error(None, update)
  File "/Users/ba/Documents/venv/lib/python3.7/site-packages/telegram/ext/dispatcher.py", line 530, in dispatch_error
    callback(self.bot, update, error)
TypeError: error() takes 2 positional arguments but 3 were given
2020-04-10 03:42:27,962 - telegram.vendor.ptb_urllib3.urllib3.connectionpool - WARNING - Retrying (Retry(total=2, connect=None, read=None, redirect=None)) after connection broken by 'NewConnectionError('<telegram.vendor.ptb_urllib3.urllib3.connection.VerifiedHTTPSConnection object at 0x111fe8a90>: Failed to establish a new connection: [Errno 61] Connection refused')': /bot1241247575:AAF_4zWZ9PAwDzXEMXBR1UpZqIu-apaNee4/getUpdates
2020-04-10 03:42:27,987 - telegram.vendor.ptb_urllib3.urllib3.connectionpool - WARNING - Retrying (Retry(total=1, connect=None, read=None, redirect=None)) after connection broken by 'NewConnectionError('<telegram.vendor.ptb_urllib3.urllib3.connection.VerifiedHTTPSConnection object at 0x112006b00>: Failed to establish a new connection: [Errno 61] Connection refused')': /bot1241247575:AAF_4zWZ9PAwDzXEMXBR1UpZqIu-apaNee4/getUpdates
2020-04-10 03:42:28,013 - telegram.vendor.ptb_urllib3.urllib3.connectionpool - WARNING - Retrying (Retry(total=0, connect=None, read=None, redirect=None)) after connection broken by 'NewConnectionError('<telegram.vendor.ptb_urllib3.urllib3.connection.VerifiedHTTPSConnection object at 0x112006a58>: Failed to establish a new connection: [Errno 61] Connection refused')': /bot1241247575:AAF_4zWZ9PAwDzXEMXBR1UpZqIu-apaNee4/getUpdates
2020-04-10 03:42:28,037 - telegram.ext.updater - ERROR - Error while getting Updates: urllib3 HTTPError HTTPSConnectionPool(host='api.telegram.org', port=443): Max retries exceeded with url: /bot1241247575:AAF_4zWZ9PAwDzXEMXBR1UpZqIu-apaNee4/getUpdates (Caused by NewConnectionError('<telegram.vendor.ptb_urllib3.urllib3.connection.VerifiedHTTPSConnection object at 0x1120060f0>: Failed to establish a new connection: [Errno 61] Connection refused'))
2020-04-10 03:42:28,037 - telegram.ext.dispatcher - ERROR - An uncaught error was raised while handling the error
Traceback (most recent call last):
  File "/Users/ba/Documents/venv/lib/python3.7/site-packages/telegram/ext/dispatcher.py", line 376, in process_update
    self.dispatch_error(None, update)
  File "/Users/ba/Documents/venv/lib/python3.7/site-packages/telegram/ext/dispatcher.py", line 530, in dispatch_error
    callback(self.bot, update, error)
TypeError: error() takes 2 positional arguments but 3 were given
2020-04-10 03:42:35,666 - telegram.vendor.ptb_urllib3.urllib3.connectionpool - WARNING - Retrying (Retry(total=2, connect=None, read=None, redirect=None)) after connection broken by 'NewConnectionError('<telegram.vendor.ptb_urllib3.urllib3.connection.VerifiedHTTPSConnection object at 0x112006908>: Failed to establish a new connection: [Errno 61] Connection refused')': /bot1241247575:AAF_4zWZ9PAwDzXEMXBR1UpZqIu-apaNee4/getUpdates
2020-04-10 03:42:35,699 - telegram.vendor.ptb_urllib3.urllib3.connectionpool - WARNING - Retrying (Retry(total=1, connect=None, read=None, redirect=None)) after connection broken by 'NewConnectionError('<telegram.vendor.ptb_urllib3.urllib3.connection.VerifiedHTTPSConnection object at 0x112006c88>: Failed to establish a new connection: [Errno 61] Connection refused')': /bot1241247575:AAF_4zWZ9PAwDzXEMXBR1UpZqIu-apaNee4/getUpdates
2020-04-10 03:42:35,725 - telegram.vendor.ptb_urllib3.urllib3.connectionpool - WARNING - Retrying (Retry(total=0, connect=None, read=None, redirect=None)) after connection broken by 'NewConnectionError('<telegram.vendor.ptb_urllib3.urllib3.connection.VerifiedHTTPSConnection object at 0x112006d30>: Failed to establish a new connection: [Errno 61] Connection refused')': /bot1241247575:AAF_4zWZ9PAwDzXEMXBR1UpZqIu-apaNee4/getUpdates
2020-04-10 03:42:35,751 - telegram.ext.updater - ERROR - Error while getting Updates: urllib3 HTTPError HTTPSConnectionPool(host='api.telegram.org', port=443): Max retries exceeded with url: /bot1241247575:AAF_4zWZ9PAwDzXEMXBR1UpZqIu-apaNee4/getUpdates (Caused by NewConnectionError('<telegram.vendor.ptb_urllib3.urllib3.connection.VerifiedHTTPSConnection object at 0x112006e10>: Failed to establish a new connection: [Errno 61] Connection refused'))
2020-04-10 03:42:35,752 - telegram.ext.dispatcher - ERROR - An uncaught error was raised while handling the error
Traceback (most recent call last):
  File "/Users/ba/Documents/venv/lib/python3.7/site-packages/telegram/ext/dispatcher.py", line 376, in process_update
    self.dispatch_error(None, update)
  File "/Users/ba/Documents/venv/lib/python3.7/site-packages/telegram/ext/dispatcher.py", line 530, in dispatch_error
    callback(self.bot, update, error)
TypeError: error() takes 2 positional arguments but 3 were given
2020-04-10 03:42:47,192 - telegram.vendor.ptb_urllib3.urllib3.connectionpool - WARNING - Retrying (Retry(total=2, connect=None, read=None, redirect=None)) after connection broken by 'NewConnectionError('<telegram.vendor.ptb_urllib3.urllib3.connection.VerifiedHTTPSConnection object at 0x11201a128>: Failed to establish a new connection: [Errno 61] Connection refused')': /bot1241247575:AAF_4zWZ9PAwDzXEMXBR1UpZqIu-apaNee4/getUpdates
2020-04-10 03:42:47,217 - telegram.vendor.ptb_urllib3.urllib3.connectionpool - WARNING - Retrying (Retry(total=1, connect=None, read=None, redirect=None)) after connection broken by 'NewConnectionError('<telegram.vendor.ptb_urllib3.urllib3.connection.VerifiedHTTPSConnection object at 0x11201a208>: Failed to establish a new connection: [Errno 61] Connection refused')': /bot1241247575:AAF_4zWZ9PAwDzXEMXBR1UpZqIu-apaNee4/getUpdates
2020-04-10 03:42:47,241 - telegram.vendor.ptb_urllib3.urllib3.connectionpool - WARNING - Retrying (Retry(total=0, connect=None, read=None, redirect=None)) after connection broken by 'NewConnectionError('<telegram.vendor.ptb_urllib3.urllib3.connection.VerifiedHTTPSConnection object at 0x11201a2b0>: Failed to establish a new connection: [Errno 61] Connection refused')': /bot1241247575:AAF_4zWZ9PAwDzXEMXBR1UpZqIu-apaNee4/getUpdates
2020-04-10 03:42:47,266 - telegram.ext.updater - ERROR - Error while getting Updates: urllib3 HTTPError HTTPSConnectionPool(host='api.telegram.org', port=443): Max retries exceeded with url: /bot1241247575:AAF_4zWZ9PAwDzXEMXBR1UpZqIu-apaNee4/getUpdates (Caused by NewConnectionError('<telegram.vendor.ptb_urllib3.urllib3.connection.VerifiedHTTPSConnection object at 0x11201a390>: Failed to establish a new connection: [Errno 61] Connection refused'))
2020-04-10 03:42:47,266 - telegram.ext.dispatcher - ERROR - An uncaught error was raised while handling the error
Traceback (most recent call last):
  File "/Users/ba/Documents/venv/lib/python3.7/site-packages/telegram/ext/dispatcher.py", line 376, in process_update
    self.dispatch_error(None, update)
  File "/Users/ba/Documents/venv/lib/python3.7/site-packages/telegram/ext/dispatcher.py", line 530, in dispatch_error
    callback(self.bot, update, error)
TypeError: error() takes 2 positional arguments but 3 were given
2020-04-10 03:43:04,393 - telegram.vendor.ptb_urllib3.urllib3.connectionpool - WARNING - Retrying (Retry(total=2, connect=None, read=None, redirect=None)) after connection broken by 'NewConnectionError('<telegram.vendor.ptb_urllib3.urllib3.connection.VerifiedHTTPSConnection object at 0x11201a0b8>: Failed to establish a new connection: [Errno 61] Connection refused')': /bot1241247575:AAF_4zWZ9PAwDzXEMXBR1UpZqIu-apaNee4/getUpdates
2020-04-10 03:43:04,417 - telegram.vendor.ptb_urllib3.urllib3.connectionpool - WARNING - Retrying (Retry(total=1, connect=None, read=None, redirect=None)) after connection broken by 'NewConnectionError('<telegram.vendor.ptb_urllib3.urllib3.connection.VerifiedHTTPSConnection object at 0x11201a748>: Failed to establish a new connection: [Errno 61] Connection refused')': /bot1241247575:AAF_4zWZ9PAwDzXEMXBR1UpZqIu-apaNee4/getUpdates
2020-04-10 03:43:04,442 - telegram.vendor.ptb_urllib3.urllib3.connectionpool - WARNING - Retrying (Retry(total=0, connect=None, read=None, redirect=None)) after connection broken by 'NewConnectionError('<telegram.vendor.ptb_urllib3.urllib3.connection.VerifiedHTTPSConnection object at 0x11201a7f0>: Failed to establish a new connection: [Errno 61] Connection refused')': /bot1241247575:AAF_4zWZ9PAwDzXEMXBR1UpZqIu-apaNee4/getUpdates
2020-04-10 03:43:04,467 - telegram.ext.updater - ERROR - Error while getting Updates: urllib3 HTTPError HTTPSConnectionPool(host='api.telegram.org', port=443): Max retries exceeded with url: /bot1241247575:AAF_4zWZ9PAwDzXEMXBR1UpZqIu-apaNee4/getUpdates (Caused by NewConnectionError('<telegram.vendor.ptb_urllib3.urllib3.connection.VerifiedHTTPSConnection object at 0x112006208>: Failed to establish a new connection: [Errno 61] Connection refused'))
2020-04-10 03:43:04,468 - telegram.ext.dispatcher - ERROR - An uncaught error was raised while handling the error
Traceback (most recent call last):
  File "/Users/ba/Documents/venv/lib/python3.7/site-packages/telegram/ext/dispatcher.py", line 376, in process_update
    self.dispatch_error(None, update)
  File "/Users/ba/Documents/venv/lib/python3.7/site-packages/telegram/ext/dispatcher.py", line 530, in dispatch_error
    callback(self.bot, update, error)
TypeError: error() takes 2 positional arguments but 3 were given
2020-04-10 03:43:30,134 - telegram.vendor.ptb_urllib3.urllib3.connectionpool - WARNING - Retrying (Retry(total=2, connect=None, read=None, redirect=None)) after connection broken by 'NewConnectionError('<telegram.vendor.ptb_urllib3.urllib3.connection.VerifiedHTTPSConnection object at 0x112006e10>: Failed to establish a new connection: [Errno 61] Connection refused')': /bot1241247575:AAF_4zWZ9PAwDzXEMXBR1UpZqIu-apaNee4/getUpdates
2020-04-10 03:43:30,165 - telegram.vendor.ptb_urllib3.urllib3.connectionpool - WARNING - Retrying (Retry(total=1, connect=None, read=None, redirect=None)) after connection broken by 'NewConnectionError('<telegram.vendor.ptb_urllib3.urllib3.connection.VerifiedHTTPSConnection object at 0x112006da0>: Failed to establish a new connection: [Errno 61] Connection refused')': /bot1241247575:AAF_4zWZ9PAwDzXEMXBR1UpZqIu-apaNee4/getUpdates
2020-04-10 03:43:30,189 - telegram.vendor.ptb_urllib3.urllib3.connectionpool - WARNING - Retrying (Retry(total=0, connect=None, read=None, redirect=None)) after connection broken by 'NewConnectionError('<telegram.vendor.ptb_urllib3.urllib3.connection.VerifiedHTTPSConnection object at 0x112006908>: Failed to establish a new connection: [Errno 61] Connection refused')': /bot1241247575:AAF_4zWZ9PAwDzXEMXBR1UpZqIu-apaNee4/getUpdates
2020-04-10 03:43:30,214 - telegram.ext.updater - ERROR - Error while getting Updates: urllib3 HTTPError HTTPSConnectionPool(host='api.telegram.org', port=443): Max retries exceeded with url: /bot1241247575:AAF_4zWZ9PAwDzXEMXBR1UpZqIu-apaNee4/getUpdates (Caused by NewConnectionError('<telegram.vendor.ptb_urllib3.urllib3.connection.VerifiedHTTPSConnection object at 0x112006a90>: Failed to establish a new connection: [Errno 61] Connection refused'))
2020-04-10 03:43:30,214 - telegram.ext.dispatcher - ERROR - An uncaught error was raised while handling the error
Traceback (most recent call last):
  File "/Users/ba/Documents/venv/lib/python3.7/site-packages/telegram/ext/dispatcher.py", line 376, in process_update
    self.dispatch_error(None, update)
  File "/Users/ba/Documents/venv/lib/python3.7/site-packages/telegram/ext/dispatcher.py", line 530, in dispatch_error
    callback(self.bot, update, error)
TypeError: error() takes 2 positional arguments but 3 were given
2020-04-10 03:44:08,693 - telegram.vendor.ptb_urllib3.urllib3.connectionpool - WARNING - Retrying (Retry(total=2, connect=None, read=None, redirect=None)) after connection broken by 'NewConnectionError('<telegram.vendor.ptb_urllib3.urllib3.connection.VerifiedHTTPSConnection object at 0x112006cf8>: Failed to establish a new connection: [Errno 61] Connection refused')': /bot1241247575:AAF_4zWZ9PAwDzXEMXBR1UpZqIu-apaNee4/getUpdates
2020-04-10 03:44:08,718 - telegram.vendor.ptb_urllib3.urllib3.connectionpool - WARNING - Retrying (Retry(total=1, connect=None, read=None, redirect=None)) after connection broken by 'NewConnectionError('<telegram.vendor.ptb_urllib3.urllib3.connection.VerifiedHTTPSConnection object at 0x111f79a58>: Failed to establish a new connection: [Errno 61] Connection refused')': /bot1241247575:AAF_4zWZ9PAwDzXEMXBR1UpZqIu-apaNee4/getUpdates
2020-04-10 03:44:08,747 - telegram.vendor.ptb_urllib3.urllib3.connectionpool - WARNING - Retrying (Retry(total=0, connect=None, read=None, redirect=None)) after connection broken by 'NewConnectionError('<telegram.vendor.ptb_urllib3.urllib3.connection.VerifiedHTTPSConnection object at 0x111f79dd8>: Failed to establish a new connection: [Errno 61] Connection refused')': /bot1241247575:AAF_4zWZ9PAwDzXEMXBR1UpZqIu-apaNee4/getUpdates
2020-04-10 03:44:08,772 - telegram.ext.updater - ERROR - Error while getting Updates: urllib3 HTTPError HTTPSConnectionPool(host='api.telegram.org', port=443): Max retries exceeded with url: /bot1241247575:AAF_4zWZ9PAwDzXEMXBR1UpZqIu-apaNee4/getUpdates (Caused by NewConnectionError('<telegram.vendor.ptb_urllib3.urllib3.connection.VerifiedHTTPSConnection object at 0x111f795c0>: Failed to establish a new connection: [Errno 61] Connection refused'))
2020-04-10 03:44:08,772 - telegram.ext.dispatcher - ERROR - An uncaught error was raised while handling the error
Traceback (most recent call last):
  File "/Users/ba/Documents/venv/lib/python3.7/site-packages/telegram/ext/dispatcher.py", line 376, in process_update
    self.dispatch_error(None, update)
  File "/Users/ba/Documents/venv/lib/python3.7/site-packages/telegram/ext/dispatcher.py", line 530, in dispatch_error
    callback(self.bot, update, error)
TypeError: error() takes 2 positional arguments but 3 were given
2020-04-10 03:44:38,815 - telegram.vendor.ptb_urllib3.urllib3.connectionpool - WARNING - Retrying (Retry(total=2, connect=None, read=None, redirect=None)) after connection broken by 'NewConnectionError('<telegram.vendor.ptb_urllib3.urllib3.connection.VerifiedHTTPSConnection object at 0x111fe8a20>: Failed to establish a new connection: [Errno 61] Connection refused')': /bot1241247575:AAF_4zWZ9PAwDzXEMXBR1UpZqIu-apaNee4/getUpdates
2020-04-10 03:44:38,843 - telegram.vendor.ptb_urllib3.urllib3.connectionpool - WARNING - Retrying (Retry(total=1, connect=None, read=None, redirect=None)) after connection broken by 'NewConnectionError('<telegram.vendor.ptb_urllib3.urllib3.connection.VerifiedHTTPSConnection object at 0x111fe8908>: Failed to establish a new connection: [Errno 61] Connection refused')': /bot1241247575:AAF_4zWZ9PAwDzXEMXBR1UpZqIu-apaNee4/getUpdates
2020-04-10 03:44:38,870 - telegram.vendor.ptb_urllib3.urllib3.connectionpool - WARNING - Retrying (Retry(total=0, connect=None, read=None, redirect=None)) after connection broken by 'NewConnectionError('<telegram.vendor.ptb_urllib3.urllib3.connection.VerifiedHTTPSConnection object at 0x111fe8978>: Failed to establish a new connection: [Errno 61] Connection refused')': /bot1241247575:AAF_4zWZ9PAwDzXEMXBR1UpZqIu-apaNee4/getUpdates
2020-04-10 03:44:38,895 - telegram.ext.updater - ERROR - Error while getting Updates: urllib3 HTTPError HTTPSConnectionPool(host='api.telegram.org', port=443): Max retries exceeded with url: /bot1241247575:AAF_4zWZ9PAwDzXEMXBR1UpZqIu-apaNee4/getUpdates (Caused by NewConnectionError('<telegram.vendor.ptb_urllib3.urllib3.connection.VerifiedHTTPSConnection object at 0x111fe8eb8>: Failed to establish a new connection: [Errno 61] Connection refused'))
2020-04-10 03:44:38,895 - telegram.ext.dispatcher - ERROR - An uncaught error was raised while handling the error
Traceback (most recent call last):
  File "/Users/ba/Documents/venv/lib/python3.7/site-packages/telegram/ext/dispatcher.py", line 376, in process_update
    self.dispatch_error(None, update)
  File "/Users/ba/Documents/venv/lib/python3.7/site-packages/telegram/ext/dispatcher.py", line 530, in dispatch_error
    callback(self.bot, update, error)
TypeError: error() takes 2 positional arguments but 3 were given
2020-04-10 03:45:08,939 - telegram.vendor.ptb_urllib3.urllib3.connectionpool - WARNING - Retrying (Retry(total=2, connect=None, read=None, redirect=None)) after connection broken by 'NewConnectionError('<telegram.vendor.ptb_urllib3.urllib3.connection.VerifiedHTTPSConnection object at 0x11201a5f8>: Failed to establish a new connection: [Errno 61] Connection refused')': /bot1241247575:AAF_4zWZ9PAwDzXEMXBR1UpZqIu-apaNee4/getUpdates
2020-04-10 03:45:08,965 - telegram.vendor.ptb_urllib3.urllib3.connectionpool - WARNING - Retrying (Retry(total=1, connect=None, read=None, redirect=None)) after connection broken by 'NewConnectionError('<telegram.vendor.ptb_urllib3.urllib3.connection.VerifiedHTTPSConnection object at 0x11201a978>: Failed to establish a new connection: [Errno 61] Connection refused')': /bot1241247575:AAF_4zWZ9PAwDzXEMXBR1UpZqIu-apaNee4/getUpdates
2020-04-10 03:45:08,990 - telegram.vendor.ptb_urllib3.urllib3.connectionpool - WARNING - Retrying (Retry(total=0, connect=None, read=None, redirect=None)) after connection broken by 'NewConnectionError('<telegram.vendor.ptb_urllib3.urllib3.connection.VerifiedHTTPSConnection object at 0x11201aa58>: Failed to establish a new connection: [Errno 61] Connection refused')': /bot1241247575:AAF_4zWZ9PAwDzXEMXBR1UpZqIu-apaNee4/getUpdates
2020-04-10 03:45:09,018 - telegram.ext.updater - ERROR - Error while getting Updates: urllib3 HTTPError HTTPSConnectionPool(host='api.telegram.org', port=443): Max retries exceeded with url: /bot1241247575:AAF_4zWZ9PAwDzXEMXBR1UpZqIu-apaNee4/getUpdates (Caused by NewConnectionError('<telegram.vendor.ptb_urllib3.urllib3.connection.VerifiedHTTPSConnection object at 0x11201ab38>: Failed to establish a new connection: [Errno 61] Connection refused'))
2020-04-10 03:45:09,018 - telegram.ext.dispatcher - ERROR - An uncaught error was raised while handling the error
Traceback (most recent call last):
  File "/Users/ba/Documents/venv/lib/python3.7/site-packages/telegram/ext/dispatcher.py", line 376, in process_update
    self.dispatch_error(None, update)
  File "/Users/ba/Documents/venv/lib/python3.7/site-packages/telegram/ext/dispatcher.py", line 530, in dispatch_error
    callback(self.bot, update, error)
TypeError: error() takes 2 positional arguments but 3 were given
2020-04-10 03:45:39,060 - telegram.vendor.ptb_urllib3.urllib3.connectionpool - WARNING - Retrying (Retry(total=2, connect=None, read=None, redirect=None)) after connection broken by 'NewConnectionError('<telegram.vendor.ptb_urllib3.urllib3.connection.VerifiedHTTPSConnection object at 0x11201a908>: Failed to establish a new connection: [Errno 61] Connection refused')': /bot1241247575:AAF_4zWZ9PAwDzXEMXBR1UpZqIu-apaNee4/getUpdates
2020-04-10 03:45:39,086 - telegram.vendor.ptb_urllib3.urllib3.connectionpool - WARNING - Retrying (Retry(total=1, connect=None, read=None, redirect=None)) after connection broken by 'NewConnectionError('<telegram.vendor.ptb_urllib3.urllib3.connection.VerifiedHTTPSConnection object at 0x11201aef0>: Failed to establish a new connection: [Errno 61] Connection refused')': /bot1241247575:AAF_4zWZ9PAwDzXEMXBR1UpZqIu-apaNee4/getUpdates
2020-04-10 03:45:39,111 - telegram.vendor.ptb_urllib3.urllib3.connectionpool - WARNING - Retrying (Retry(total=0, connect=None, read=None, redirect=None)) after connection broken by 'NewConnectionError('<telegram.vendor.ptb_urllib3.urllib3.connection.VerifiedHTTPSConnection object at 0x11201af98>: Failed to establish a new connection: [Errno 61] Connection refused')': /bot1241247575:AAF_4zWZ9PAwDzXEMXBR1UpZqIu-apaNee4/getUpdates
2020-04-10 03:45:39,139 - telegram.ext.updater - ERROR - Error while getting Updates: urllib3 HTTPError HTTPSConnectionPool(host='api.telegram.org', port=443): Max retries exceeded with url: /bot1241247575:AAF_4zWZ9PAwDzXEMXBR1UpZqIu-apaNee4/getUpdates (Caused by NewConnectionError('<telegram.vendor.ptb_urllib3.urllib3.connection.VerifiedHTTPSConnection object at 0x11202d0b8>: Failed to establish a new connection: [Errno 61] Connection refused'))
2020-04-10 03:45:39,139 - telegram.ext.dispatcher - ERROR - An uncaught error was raised while handling the error
Traceback (most recent call last):
  File "/Users/ba/Documents/venv/lib/python3.7/site-packages/telegram/ext/dispatcher.py", line 376, in process_update
    self.dispatch_error(None, update)
  File "/Users/ba/Documents/venv/lib/python3.7/site-packages/telegram/ext/dispatcher.py", line 530, in dispatch_error
    callback(self.bot, update, error)
TypeError: error() takes 2 positional arguments but 3 were given
2020-04-10 04:02:28,168 - telegram.vendor.ptb_urllib3.urllib3.connectionpool - WARNING - Retrying (Retry(total=2, connect=None, read=None, redirect=None)) after connection broken by 'NewConnectionError('<telegram.vendor.ptb_urllib3.urllib3.connection.VerifiedHTTPSConnection object at 0x11202d390>: Failed to establish a new connection: [Errno 50] Network is down')': /bot1241247575:AAF_4zWZ9PAwDzXEMXBR1UpZqIu-apaNee4/getUpdates
2020-04-10 04:02:29,342 - telegram.vendor.ptb_urllib3.urllib3.connectionpool - WARNING - Retrying (Retry(total=1, connect=None, read=None, redirect=None)) after connection broken by 'NewConnectionError('<telegram.vendor.ptb_urllib3.urllib3.connection.VerifiedHTTPSConnection object at 0x11202d470>: Failed to establish a new connection: [Errno 61] Connection refused')': /bot1241247575:AAF_4zWZ9PAwDzXEMXBR1UpZqIu-apaNee4/getUpdates
2020-04-10 04:02:29,368 - telegram.vendor.ptb_urllib3.urllib3.connectionpool - WARNING - Retrying (Retry(total=0, connect=None, read=None, redirect=None)) after connection broken by 'NewConnectionError('<telegram.vendor.ptb_urllib3.urllib3.connection.VerifiedHTTPSConnection object at 0x11201a898>: Failed to establish a new connection: [Errno 61] Connection refused')': /bot1241247575:AAF_4zWZ9PAwDzXEMXBR1UpZqIu-apaNee4/getUpdates
2020-04-10 04:02:29,404 - telegram.ext.updater - ERROR - Error while getting Updates: urllib3 HTTPError HTTPSConnectionPool(host='api.telegram.org', port=443): Max retries exceeded with url: /bot1241247575:AAF_4zWZ9PAwDzXEMXBR1UpZqIu-apaNee4/getUpdates (Caused by NewConnectionError('<telegram.vendor.ptb_urllib3.urllib3.connection.VerifiedHTTPSConnection object at 0x11201aa20>: Failed to establish a new connection: [Errno 61] Connection refused'))
2020-04-10 04:02:29,405 - telegram.ext.dispatcher - ERROR - An uncaught error was raised while handling the error
Traceback (most recent call last):
  File "/Users/ba/Documents/venv/lib/python3.7/site-packages/telegram/ext/dispatcher.py", line 376, in process_update
    self.dispatch_error(None, update)
  File "/Users/ba/Documents/venv/lib/python3.7/site-packages/telegram/ext/dispatcher.py", line 530, in dispatch_error
    callback(self.bot, update, error)
TypeError: error() takes 2 positional arguments but 3 were given
2020-04-10 04:02:59,655 - telegram.vendor.ptb_urllib3.urllib3.connectionpool - WARNING - Retrying (Retry(total=2, connect=None, read=None, redirect=None)) after connection broken by 'NewConnectionError('<telegram.vendor.ptb_urllib3.urllib3.connection.VerifiedHTTPSConnection object at 0x111fe8fd0>: Failed to establish a new connection: [Errno 61] Connection refused')': /bot1241247575:AAF_4zWZ9PAwDzXEMXBR1UpZqIu-apaNee4/getUpdates
2020-04-10 04:02:59,683 - telegram.vendor.ptb_urllib3.urllib3.connectionpool - WARNING - Retrying (Retry(total=1, connect=None, read=None, redirect=None)) after connection broken by 'NewConnectionError('<telegram.vendor.ptb_urllib3.urllib3.connection.VerifiedHTTPSConnection object at 0x111fe89e8>: Failed to establish a new connection: [Errno 61] Connection refused')': /bot1241247575:AAF_4zWZ9PAwDzXEMXBR1UpZqIu-apaNee4/getUpdates
2020-04-10 04:02:59,787 - telegram.vendor.ptb_urllib3.urllib3.connectionpool - WARNING - Retrying (Retry(total=0, connect=None, read=None, redirect=None)) after connection broken by 'NewConnectionError('<telegram.vendor.ptb_urllib3.urllib3.connection.VerifiedHTTPSConnection object at 0x111fe8518>: Failed to establish a new connection: [Errno 61] Connection refused')': /bot1241247575:AAF_4zWZ9PAwDzXEMXBR1UpZqIu-apaNee4/getUpdates
2020-04-10 04:02:59,813 - telegram.ext.updater - ERROR - Error while getting Updates: urllib3 HTTPError HTTPSConnectionPool(host='api.telegram.org', port=443): Max retries exceeded with url: /bot1241247575:AAF_4zWZ9PAwDzXEMXBR1UpZqIu-apaNee4/getUpdates (Caused by NewConnectionError('<telegram.vendor.ptb_urllib3.urllib3.connection.VerifiedHTTPSConnection object at 0x111fe8748>: Failed to establish a new connection: [Errno 61] Connection refused'))
2020-04-10 04:02:59,813 - telegram.ext.dispatcher - ERROR - An uncaught error was raised while handling the error
Traceback (most recent call last):
  File "/Users/ba/Documents/venv/lib/python3.7/site-packages/telegram/ext/dispatcher.py", line 376, in process_update
    self.dispatch_error(None, update)
  File "/Users/ba/Documents/venv/lib/python3.7/site-packages/telegram/ext/dispatcher.py", line 530, in dispatch_error
    callback(self.bot, update, error)
TypeError: error() takes 2 positional arguments but 3 were given
2020-04-10 04:03:29,964 - telegram.vendor.ptb_urllib3.urllib3.connectionpool - WARNING - Retrying (Retry(total=2, connect=None, read=None, redirect=None)) after connection broken by 'NewConnectionError('<telegram.vendor.ptb_urllib3.urllib3.connection.VerifiedHTTPSConnection object at 0x111fe8cf8>: Failed to establish a new connection: [Errno 61] Connection refused')': /bot1241247575:AAF_4zWZ9PAwDzXEMXBR1UpZqIu-apaNee4/getUpdates
2020-04-10 04:03:30,100 - telegram.vendor.ptb_urllib3.urllib3.connectionpool - WARNING - Retrying (Retry(total=1, connect=None, read=None, redirect=None)) after connection broken by 'NewConnectionError('<telegram.vendor.ptb_urllib3.urllib3.connection.VerifiedHTTPSConnection object at 0x111f79f98>: Failed to establish a new connection: [Errno 61] Connection refused')': /bot1241247575:AAF_4zWZ9PAwDzXEMXBR1UpZqIu-apaNee4/getUpdates
2020-04-10 04:03:30,262 - telegram.vendor.ptb_urllib3.urllib3.connectionpool - WARNING - Retrying (Retry(total=0, connect=None, read=None, redirect=None)) after connection broken by 'NewConnectionError('<telegram.vendor.ptb_urllib3.urllib3.connection.VerifiedHTTPSConnection object at 0x111f79828>: Failed to establish a new connection: [Errno 61] Connection refused')': /bot1241247575:AAF_4zWZ9PAwDzXEMXBR1UpZqIu-apaNee4/getUpdates
2020-04-10 04:03:30,392 - telegram.ext.updater - ERROR - Error while getting Updates: urllib3 HTTPError HTTPSConnectionPool(host='api.telegram.org', port=443): Max retries exceeded with url: /bot1241247575:AAF_4zWZ9PAwDzXEMXBR1UpZqIu-apaNee4/getUpdates (Caused by NewConnectionError('<telegram.vendor.ptb_urllib3.urllib3.connection.VerifiedHTTPSConnection object at 0x111f790b8>: Failed to establish a new connection: [Errno 61] Connection refused'))
2020-04-10 04:03:30,393 - telegram.ext.dispatcher - ERROR - An uncaught error was raised while handling the error
Traceback (most recent call last):
  File "/Users/ba/Documents/venv/lib/python3.7/site-packages/telegram/ext/dispatcher.py", line 376, in process_update
    self.dispatch_error(None, update)
  File "/Users/ba/Documents/venv/lib/python3.7/site-packages/telegram/ext/dispatcher.py", line 530, in dispatch_error
    callback(self.bot, update, error)
TypeError: error() takes 2 positional arguments but 3 were given
2020-04-10 04:04:00,433 - telegram.vendor.ptb_urllib3.urllib3.connectionpool - WARNING - Retrying (Retry(total=2, connect=None, read=None, redirect=None)) after connection broken by 'NewConnectionError('<telegram.vendor.ptb_urllib3.urllib3.connection.VerifiedHTTPSConnection object at 0x112006b00>: Failed to establish a new connection: [Errno 61] Connection refused')': /bot1241247575:AAF_4zWZ9PAwDzXEMXBR1UpZqIu-apaNee4/getUpdates
2020-04-10 04:04:00,459 - telegram.vendor.ptb_urllib3.urllib3.connectionpool - WARNING - Retrying (Retry(total=1, connect=None, read=None, redirect=None)) after connection broken by 'NewConnectionError('<telegram.vendor.ptb_urllib3.urllib3.connection.VerifiedHTTPSConnection object at 0x112006cf8>: Failed to establish a new connection: [Errno 61] Connection refused')': /bot1241247575:AAF_4zWZ9PAwDzXEMXBR1UpZqIu-apaNee4/getUpdates
2020-04-10 04:04:00,483 - telegram.vendor.ptb_urllib3.urllib3.connectionpool - WARNING - Retrying (Retry(total=0, connect=None, read=None, redirect=None)) after connection broken by 'NewConnectionError('<telegram.vendor.ptb_urllib3.urllib3.connection.VerifiedHTTPSConnection object at 0x112006e48>: Failed to establish a new connection: [Errno 61] Connection refused')': /bot1241247575:AAF_4zWZ9PAwDzXEMXBR1UpZqIu-apaNee4/getUpdates
2020-04-10 04:04:00,509 - telegram.ext.updater - ERROR - Error while getting Updates: urllib3 HTTPError HTTPSConnectionPool(host='api.telegram.org', port=443): Max retries exceeded with url: /bot1241247575:AAF_4zWZ9PAwDzXEMXBR1UpZqIu-apaNee4/getUpdates (Caused by NewConnectionError('<telegram.vendor.ptb_urllib3.urllib3.connection.VerifiedHTTPSConnection object at 0x112006d30>: Failed to establish a new connection: [Errno 61] Connection refused'))
2020-04-10 04:04:00,509 - telegram.ext.dispatcher - ERROR - An uncaught error was raised while handling the error
Traceback (most recent call last):
  File "/Users/ba/Documents/venv/lib/python3.7/site-packages/telegram/ext/dispatcher.py", line 376, in process_update
    self.dispatch_error(None, update)
  File "/Users/ba/Documents/venv/lib/python3.7/site-packages/telegram/ext/dispatcher.py", line 530, in dispatch_error
    callback(self.bot, update, error)
TypeError: error() takes 2 positional arguments but 3 were given
2020-04-10 04:04:30,544 - telegram.vendor.ptb_urllib3.urllib3.connectionpool - WARNING - Retrying (Retry(total=2, connect=None, read=None, redirect=None)) after connection broken by 'NewConnectionError('<telegram.vendor.ptb_urllib3.urllib3.connection.VerifiedHTTPSConnection object at 0x1120060f0>: Failed to establish a new connection: [Errno 61] Connection refused')': /bot1241247575:AAF_4zWZ9PAwDzXEMXBR1UpZqIu-apaNee4/getUpdates
2020-04-10 04:04:30,567 - telegram.vendor.ptb_urllib3.urllib3.connectionpool - WARNING - Retrying (Retry(total=1, connect=None, read=None, redirect=None)) after connection broken by 'NewConnectionError('<telegram.vendor.ptb_urllib3.urllib3.connection.VerifiedHTTPSConnection object at 0x112006e10>: Failed to establish a new connection: [Errno 61] Connection refused')': /bot1241247575:AAF_4zWZ9PAwDzXEMXBR1UpZqIu-apaNee4/getUpdates
2020-04-10 04:04:30,592 - telegram.vendor.ptb_urllib3.urllib3.connectionpool - WARNING - Retrying (Retry(total=0, connect=None, read=None, redirect=None)) after connection broken by 'NewConnectionError('<telegram.vendor.ptb_urllib3.urllib3.connection.VerifiedHTTPSConnection object at 0x11202d320>: Failed to establish a new connection: [Errno 61] Connection refused')': /bot1241247575:AAF_4zWZ9PAwDzXEMXBR1UpZqIu-apaNee4/getUpdates
2020-04-10 04:04:30,616 - telegram.ext.updater - ERROR - Error while getting Updates: urllib3 HTTPError HTTPSConnectionPool(host='api.telegram.org', port=443): Max retries exceeded with url: /bot1241247575:AAF_4zWZ9PAwDzXEMXBR1UpZqIu-apaNee4/getUpdates (Caused by NewConnectionError('<telegram.vendor.ptb_urllib3.urllib3.connection.VerifiedHTTPSConnection object at 0x11202d518>: Failed to establish a new connection: [Errno 61] Connection refused'))
2020-04-10 04:04:30,617 - telegram.ext.dispatcher - ERROR - An uncaught error was raised while handling the error
Traceback (most recent call last):
  File "/Users/ba/Documents/venv/lib/python3.7/site-packages/telegram/ext/dispatcher.py", line 376, in process_update
    self.dispatch_error(None, update)
  File "/Users/ba/Documents/venv/lib/python3.7/site-packages/telegram/ext/dispatcher.py", line 530, in dispatch_error
    callback(self.bot, update, error)
TypeError: error() takes 2 positional arguments but 3 were given
2020-04-10 04:05:00,652 - telegram.vendor.ptb_urllib3.urllib3.connectionpool - WARNING - Retrying (Retry(total=2, connect=None, read=None, redirect=None)) after connection broken by 'NewConnectionError('<telegram.vendor.ptb_urllib3.urllib3.connection.VerifiedHTTPSConnection object at 0x11202d828>: Failed to establish a new connection: [Errno 61] Connection refused')': /bot1241247575:AAF_4zWZ9PAwDzXEMXBR1UpZqIu-apaNee4/getUpdates
2020-04-10 04:05:00,685 - telegram.vendor.ptb_urllib3.urllib3.connectionpool - WARNING - Retrying (Retry(total=1, connect=None, read=None, redirect=None)) after connection broken by 'NewConnectionError('<telegram.vendor.ptb_urllib3.urllib3.connection.VerifiedHTTPSConnection object at 0x11202d908>: Failed to establish a new connection: [Errno 61] Connection refused')': /bot1241247575:AAF_4zWZ9PAwDzXEMXBR1UpZqIu-apaNee4/getUpdates
2020-04-10 04:05:00,709 - telegram.vendor.ptb_urllib3.urllib3.connectionpool - WARNING - Retrying (Retry(total=0, connect=None, read=None, redirect=None)) after connection broken by 'NewConnectionError('<telegram.vendor.ptb_urllib3.urllib3.connection.VerifiedHTTPSConnection object at 0x11202d9b0>: Failed to establish a new connection: [Errno 61] Connection refused')': /bot1241247575:AAF_4zWZ9PAwDzXEMXBR1UpZqIu-apaNee4/getUpdates
2020-04-10 04:05:00,733 - telegram.ext.updater - ERROR - Error while getting Updates: urllib3 HTTPError HTTPSConnectionPool(host='api.telegram.org', port=443): Max retries exceeded with url: /bot1241247575:AAF_4zWZ9PAwDzXEMXBR1UpZqIu-apaNee4/getUpdates (Caused by NewConnectionError('<telegram.vendor.ptb_urllib3.urllib3.connection.VerifiedHTTPSConnection object at 0x11202da90>: Failed to establish a new connection: [Errno 61] Connection refused'))
2020-04-10 04:05:00,734 - telegram.ext.dispatcher - ERROR - An uncaught error was raised while handling the error
Traceback (most recent call last):
  File "/Users/ba/Documents/venv/lib/python3.7/site-packages/telegram/ext/dispatcher.py", line 376, in process_update
    self.dispatch_error(None, update)
  File "/Users/ba/Documents/venv/lib/python3.7/site-packages/telegram/ext/dispatcher.py", line 530, in dispatch_error
    callback(self.bot, update, error)
TypeError: error() takes 2 positional arguments but 3 were given
2020-04-10 04:05:30,773 - telegram.vendor.ptb_urllib3.urllib3.connectionpool - WARNING - Retrying (Retry(total=2, connect=None, read=None, redirect=None)) after connection broken by 'NewConnectionError('<telegram.vendor.ptb_urllib3.urllib3.connection.VerifiedHTTPSConnection object at 0x11202d7b8>: Failed to establish a new connection: [Errno 61] Connection refused')': /bot1241247575:AAF_4zWZ9PAwDzXEMXBR1UpZqIu-apaNee4/getUpdates
2020-04-10 04:05:30,800 - telegram.vendor.ptb_urllib3.urllib3.connectionpool - WARNING - Retrying (Retry(total=1, connect=None, read=None, redirect=None)) after connection broken by 'NewConnectionError('<telegram.vendor.ptb_urllib3.urllib3.connection.VerifiedHTTPSConnection object at 0x11202de48>: Failed to establish a new connection: [Errno 61] Connection refused')': /bot1241247575:AAF_4zWZ9PAwDzXEMXBR1UpZqIu-apaNee4/getUpdates
2020-04-10 04:05:30,833 - telegram.vendor.ptb_urllib3.urllib3.connectionpool - WARNING - Retrying (Retry(total=0, connect=None, read=None, redirect=None)) after connection broken by 'NewConnectionError('<telegram.vendor.ptb_urllib3.urllib3.connection.VerifiedHTTPSConnection object at 0x112006240>: Failed to establish a new connection: [Errno 61] Connection refused')': /bot1241247575:AAF_4zWZ9PAwDzXEMXBR1UpZqIu-apaNee4/getUpdates
2020-04-10 04:05:30,867 - telegram.ext.updater - ERROR - Error while getting Updates: urllib3 HTTPError HTTPSConnectionPool(host='api.telegram.org', port=443): Max retries exceeded with url: /bot1241247575:AAF_4zWZ9PAwDzXEMXBR1UpZqIu-apaNee4/getUpdates (Caused by NewConnectionError('<telegram.vendor.ptb_urllib3.urllib3.connection.VerifiedHTTPSConnection object at 0x112006ac8>: Failed to establish a new connection: [Errno 61] Connection refused'))
2020-04-10 04:05:30,867 - telegram.ext.dispatcher - ERROR - An uncaught error was raised while handling the error
Traceback (most recent call last):
  File "/Users/ba/Documents/venv/lib/python3.7/site-packages/telegram/ext/dispatcher.py", line 376, in process_update
    self.dispatch_error(None, update)
  File "/Users/ba/Documents/venv/lib/python3.7/site-packages/telegram/ext/dispatcher.py", line 530, in dispatch_error
    callback(self.bot, update, error)
TypeError: error() takes 2 positional arguments but 3 were given
2020-04-10 04:06:00,899 - telegram.vendor.ptb_urllib3.urllib3.connectionpool - WARNING - Retrying (Retry(total=2, connect=None, read=None, redirect=None)) after connection broken by 'NewConnectionError('<telegram.vendor.ptb_urllib3.urllib3.connection.VerifiedHTTPSConnection object at 0x112006d68>: Failed to establish a new connection: [Errno 61] Connection refused')': /bot1241247575:AAF_4zWZ9PAwDzXEMXBR1UpZqIu-apaNee4/getUpdates
2020-04-10 04:06:00,924 - telegram.vendor.ptb_urllib3.urllib3.connectionpool - WARNING - Retrying (Retry(total=1, connect=None, read=None, redirect=None)) after connection broken by 'NewConnectionError('<telegram.vendor.ptb_urllib3.urllib3.connection.VerifiedHTTPSConnection object at 0x112006c88>: Failed to establish a new connection: [Errno 61] Connection refused')': /bot1241247575:AAF_4zWZ9PAwDzXEMXBR1UpZqIu-apaNee4/getUpdates
2020-04-10 04:06:00,949 - telegram.vendor.ptb_urllib3.urllib3.connectionpool - WARNING - Retrying (Retry(total=0, connect=None, read=None, redirect=None)) after connection broken by 'NewConnectionError('<telegram.vendor.ptb_urllib3.urllib3.connection.VerifiedHTTPSConnection object at 0x112006d30>: Failed to establish a new connection: [Errno 61] Connection refused')': /bot1241247575:AAF_4zWZ9PAwDzXEMXBR1UpZqIu-apaNee4/getUpdates
2020-04-10 04:06:00,975 - telegram.ext.updater - ERROR - Error while getting Updates: urllib3 HTTPError HTTPSConnectionPool(host='api.telegram.org', port=443): Max retries exceeded with url: /bot1241247575:AAF_4zWZ9PAwDzXEMXBR1UpZqIu-apaNee4/getUpdates (Caused by NewConnectionError('<telegram.vendor.ptb_urllib3.urllib3.connection.VerifiedHTTPSConnection object at 0x112006cf8>: Failed to establish a new connection: [Errno 61] Connection refused'))
2020-04-10 04:06:00,975 - telegram.ext.dispatcher - ERROR - An uncaught error was raised while handling the error
Traceback (most recent call last):
  File "/Users/ba/Documents/venv/lib/python3.7/site-packages/telegram/ext/dispatcher.py", line 376, in process_update
    self.dispatch_error(None, update)
  File "/Users/ba/Documents/venv/lib/python3.7/site-packages/telegram/ext/dispatcher.py", line 530, in dispatch_error
    callback(self.bot, update, error)
TypeError: error() takes 2 positional arguments but 3 were given
2020-04-10 04:06:31,012 - telegram.vendor.ptb_urllib3.urllib3.connectionpool - WARNING - Retrying (Retry(total=2, connect=None, read=None, redirect=None)) after connection broken by 'NewConnectionError('<telegram.vendor.ptb_urllib3.urllib3.connection.VerifiedHTTPSConnection object at 0x111f795c0>: Failed to establish a new connection: [Errno 61] Connection refused')': /bot1241247575:AAF_4zWZ9PAwDzXEMXBR1UpZqIu-apaNee4/getUpdates
2020-04-10 04:06:31,042 - telegram.vendor.ptb_urllib3.urllib3.connectionpool - WARNING - Retrying (Retry(total=1, connect=None, read=None, redirect=None)) after connection broken by 'NewConnectionError('<telegram.vendor.ptb_urllib3.urllib3.connection.VerifiedHTTPSConnection object at 0x111f79828>: Failed to establish a new connection: [Errno 61] Connection refused')': /bot1241247575:AAF_4zWZ9PAwDzXEMXBR1UpZqIu-apaNee4/getUpdates
2020-04-10 04:06:31,066 - telegram.vendor.ptb_urllib3.urllib3.connectionpool - WARNING - Retrying (Retry(total=0, connect=None, read=None, redirect=None)) after connection broken by 'NewConnectionError('<telegram.vendor.ptb_urllib3.urllib3.connection.VerifiedHTTPSConnection object at 0x111fe8eb8>: Failed to establish a new connection: [Errno 61] Connection refused')': /bot1241247575:AAF_4zWZ9PAwDzXEMXBR1UpZqIu-apaNee4/getUpdates
2020-04-10 04:06:31,090 - telegram.ext.updater - ERROR - Error while getting Updates: urllib3 HTTPError HTTPSConnectionPool(host='api.telegram.org', port=443): Max retries exceeded with url: /bot1241247575:AAF_4zWZ9PAwDzXEMXBR1UpZqIu-apaNee4/getUpdates (Caused by NewConnectionError('<telegram.vendor.ptb_urllib3.urllib3.connection.VerifiedHTTPSConnection object at 0x111fe8be0>: Failed to establish a new connection: [Errno 61] Connection refused'))
2020-04-10 04:06:31,090 - telegram.ext.dispatcher - ERROR - An uncaught error was raised while handling the error
Traceback (most recent call last):
  File "/Users/ba/Documents/venv/lib/python3.7/site-packages/telegram/ext/dispatcher.py", line 376, in process_update
    self.dispatch_error(None, update)
  File "/Users/ba/Documents/venv/lib/python3.7/site-packages/telegram/ext/dispatcher.py", line 530, in dispatch_error
    callback(self.bot, update, error)
TypeError: error() takes 2 positional arguments but 3 were given
2020-04-10 04:07:01,129 - telegram.vendor.ptb_urllib3.urllib3.connectionpool - WARNING - Retrying (Retry(total=2, connect=None, read=None, redirect=None)) after connection broken by 'NewConnectionError('<telegram.vendor.ptb_urllib3.urllib3.connection.VerifiedHTTPSConnection object at 0x111fe88d0>: Failed to establish a new connection: [Errno 61] Connection refused')': /bot1241247575:AAF_4zWZ9PAwDzXEMXBR1UpZqIu-apaNee4/getUpdates
2020-04-10 04:07:01,167 - telegram.vendor.ptb_urllib3.urllib3.connectionpool - WARNING - Retrying (Retry(total=1, connect=None, read=None, redirect=None)) after connection broken by 'NewConnectionError('<telegram.vendor.ptb_urllib3.urllib3.connection.VerifiedHTTPSConnection object at 0x111fe8748>: Failed to establish a new connection: [Errno 61] Connection refused')': /bot1241247575:AAF_4zWZ9PAwDzXEMXBR1UpZqIu-apaNee4/getUpdates
2020-04-10 04:07:01,190 - telegram.vendor.ptb_urllib3.urllib3.connectionpool - WARNING - Retrying (Retry(total=0, connect=None, read=None, redirect=None)) after connection broken by 'NewConnectionError('<telegram.vendor.ptb_urllib3.urllib3.connection.VerifiedHTTPSConnection object at 0x111fe8240>: Failed to establish a new connection: [Errno 61] Connection refused')': /bot1241247575:AAF_4zWZ9PAwDzXEMXBR1UpZqIu-apaNee4/getUpdates
2020-04-10 04:07:01,213 - telegram.ext.updater - ERROR - Error while getting Updates: urllib3 HTTPError HTTPSConnectionPool(host='api.telegram.org', port=443): Max retries exceeded with url: /bot1241247575:AAF_4zWZ9PAwDzXEMXBR1UpZqIu-apaNee4/getUpdates (Caused by NewConnectionError('<telegram.vendor.ptb_urllib3.urllib3.connection.VerifiedHTTPSConnection object at 0x11201aac8>: Failed to establish a new connection: [Errno 61] Connection refused'))
2020-04-10 04:07:01,214 - telegram.ext.dispatcher - ERROR - An uncaught error was raised while handling the error
Traceback (most recent call last):
  File "/Users/ba/Documents/venv/lib/python3.7/site-packages/telegram/ext/dispatcher.py", line 376, in process_update
    self.dispatch_error(None, update)
  File "/Users/ba/Documents/venv/lib/python3.7/site-packages/telegram/ext/dispatcher.py", line 530, in dispatch_error
    callback(self.bot, update, error)
TypeError: error() takes 2 positional arguments but 3 were given
2020-04-10 04:07:31,253 - telegram.vendor.ptb_urllib3.urllib3.connectionpool - WARNING - Retrying (Retry(total=2, connect=None, read=None, redirect=None)) after connection broken by 'NewConnectionError('<telegram.vendor.ptb_urllib3.urllib3.connection.VerifiedHTTPSConnection object at 0x11201aa90>: Failed to establish a new connection: [Errno 61] Connection refused')': /bot1241247575:AAF_4zWZ9PAwDzXEMXBR1UpZqIu-apaNee4/getUpdates
2020-04-10 04:07:31,279 - telegram.vendor.ptb_urllib3.urllib3.connectionpool - WARNING - Retrying (Retry(total=1, connect=None, read=None, redirect=None)) after connection broken by 'NewConnectionError('<telegram.vendor.ptb_urllib3.urllib3.connection.VerifiedHTTPSConnection object at 0x11202dcf8>: Failed to establish a new connection: [Errno 61] Connection refused')': /bot1241247575:AAF_4zWZ9PAwDzXEMXBR1UpZqIu-apaNee4/getUpdates
2020-04-10 04:07:31,304 - telegram.vendor.ptb_urllib3.urllib3.connectionpool - WARNING - Retrying (Retry(total=0, connect=None, read=None, redirect=None)) after connection broken by 'NewConnectionError('<telegram.vendor.ptb_urllib3.urllib3.connection.VerifiedHTTPSConnection object at 0x11202df28>: Failed to establish a new connection: [Errno 61] Connection refused')': /bot1241247575:AAF_4zWZ9PAwDzXEMXBR1UpZqIu-apaNee4/getUpdates
2020-04-10 04:07:31,327 - telegram.ext.updater - ERROR - Error while getting Updates: urllib3 HTTPError HTTPSConnectionPool(host='api.telegram.org', port=443): Max retries exceeded with url: /bot1241247575:AAF_4zWZ9PAwDzXEMXBR1UpZqIu-apaNee4/getUpdates (Caused by NewConnectionError('<telegram.vendor.ptb_urllib3.urllib3.connection.VerifiedHTTPSConnection object at 0x11202d550>: Failed to establish a new connection: [Errno 61] Connection refused'))
2020-04-10 04:07:31,327 - telegram.ext.dispatcher - ERROR - An uncaught error was raised while handling the error
Traceback (most recent call last):
  File "/Users/ba/Documents/venv/lib/python3.7/site-packages/telegram/ext/dispatcher.py", line 376, in process_update
    self.dispatch_error(None, update)
  File "/Users/ba/Documents/venv/lib/python3.7/site-packages/telegram/ext/dispatcher.py", line 530, in dispatch_error
    callback(self.bot, update, error)
TypeError: error() takes 2 positional arguments but 3 were given
2020-04-10 04:08:01,362 - telegram.vendor.ptb_urllib3.urllib3.connectionpool - WARNING - Retrying (Retry(total=2, connect=None, read=None, redirect=None)) after connection broken by 'NewConnectionError('<telegram.vendor.ptb_urllib3.urllib3.connection.VerifiedHTTPSConnection object at 0x112040128>: Failed to establish a new connection: [Errno 61] Connection refused')': /bot1241247575:AAF_4zWZ9PAwDzXEMXBR1UpZqIu-apaNee4/getUpdates
2020-04-10 04:08:01,388 - telegram.vendor.ptb_urllib3.urllib3.connectionpool - WARNING - Retrying (Retry(total=1, connect=None, read=None, redirect=None)) after connection broken by 'NewConnectionError('<telegram.vendor.ptb_urllib3.urllib3.connection.VerifiedHTTPSConnection object at 0x112040208>: Failed to establish a new connection: [Errno 61] Connection refused')': /bot1241247575:AAF_4zWZ9PAwDzXEMXBR1UpZqIu-apaNee4/getUpdates
2020-04-10 04:08:01,410 - telegram.vendor.ptb_urllib3.urllib3.connectionpool - WARNING - Retrying (Retry(total=0, connect=None, read=None, redirect=None)) after connection broken by 'NewConnectionError('<telegram.vendor.ptb_urllib3.urllib3.connection.VerifiedHTTPSConnection object at 0x1120402b0>: Failed to establish a new connection: [Errno 61] Connection refused')': /bot1241247575:AAF_4zWZ9PAwDzXEMXBR1UpZqIu-apaNee4/getUpdates
2020-04-10 04:08:01,437 - telegram.ext.updater - ERROR - Error while getting Updates: urllib3 HTTPError HTTPSConnectionPool(host='api.telegram.org', port=443): Max retries exceeded with url: /bot1241247575:AAF_4zWZ9PAwDzXEMXBR1UpZqIu-apaNee4/getUpdates (Caused by NewConnectionError('<telegram.vendor.ptb_urllib3.urllib3.connection.VerifiedHTTPSConnection object at 0x112040390>: Failed to establish a new connection: [Errno 61] Connection refused'))
2020-04-10 04:08:01,438 - telegram.ext.dispatcher - ERROR - An uncaught error was raised while handling the error
Traceback (most recent call last):
  File "/Users/ba/Documents/venv/lib/python3.7/site-packages/telegram/ext/dispatcher.py", line 376, in process_update
    self.dispatch_error(None, update)
  File "/Users/ba/Documents/venv/lib/python3.7/site-packages/telegram/ext/dispatcher.py", line 530, in dispatch_error
    callback(self.bot, update, error)
TypeError: error() takes 2 positional arguments but 3 were given
2020-04-10 04:08:27,597 - telegram.ext.updater - INFO - Received signal 2 (SIGINT), stopping...
2020-04-10 04:08:30,230 - telegram.ext.updater - WARNING - Exiting immediately!
2020-04-10 04:11:44,958 - telegram.ext.updater - INFO - Received signal 2 (SIGINT), stopping...
2020-04-10 04:11:50,650 - telegram.ext.updater - WARNING - Exiting immediately!
2020-04-10 04:13:38,170 - telegram.ext.updater - INFO - Received signal 2 (SIGINT), stopping...
2020-04-10 04:16:00,917 - telegram.ext.updater - INFO - Received signal 2 (SIGINT), stopping...
2020-04-10 04:16:03,996 - telegram.ext.updater - WARNING - Exiting immediately!
2020-04-10 04:16:23,866 - telegram.ext.updater - INFO - Received signal 2 (SIGINT), stopping...
2020-04-10 04:16:25,511 - telegram.ext.updater - WARNING - Exiting immediately!
2020-04-10 04:21:10,880 - telegram.ext.updater - INFO - Received signal 2 (SIGINT), stopping...
2020-04-10 04:22:38,655 - telegram.ext.updater - INFO - Received signal 2 (SIGINT), stopping...
2020-04-10 04:23:27,968 - telegram.ext.updater - INFO - Received signal 2 (SIGINT), stopping...
2020-04-10 04:24:50,889 - telegram.ext.updater - INFO - Received signal 2 (SIGINT), stopping...
2020-04-10 04:26:08,921 - telegram.ext.updater - INFO - Received signal 2 (SIGINT), stopping...
2020-04-10 15:20:05,017 - telegram.ext.updater - INFO - Received signal 2 (SIGINT), stopping...
2020-04-10 15:22:46,585 - telegram.ext.updater - INFO - Received signal 2 (SIGINT), stopping...
2020-04-10 15:22:52,814 - telegram.ext.updater - WARNING - Exiting immediately!
2020-04-10 15:23:48,261 - telegram.ext.updater - INFO - Received signal 2 (SIGINT), stopping...
2020-04-10 15:25:42,170 - telegram.ext.updater - INFO - Received signal 2 (SIGINT), stopping...
2020-04-10 15:25:47,948 - telegram.ext.updater - WARNING - Exiting immediately!
2020-04-10 15:37:19,331 - telegram.ext.updater - INFO - Received signal 2 (SIGINT), stopping...
2020-04-10 15:37:21,011 - telegram.ext.updater - WARNING - Exiting immediately!
